<?xml version="1.0"?>
<robot xmlns:xacro="http://ros.org/wiki/xacro">

    <xacro:include filename="$(find nvt_description)/urdf/utils/inertia.xacro" />
    <xacro:include filename="$(find nvt_description)/urdf/wheel/wheel.gazebo.xacro"/>

    <xacro:property name="wheel_radius" value="0.1575"/>
    <xacro:property name="wheel_length" value="0.032"/>
    <xacro:property name="wheel_mass" value="2.0"/>

    <xacro:macro name="wheel_v0" params="prefix parent *joint_origin *joint_axis">
        <joint name="${prefix}_wheel_joint" type="continuous">
	        <xacro:insert_block name="joint_origin"/>
	        <parent link="${parent}"/>
	        <child link="${prefix}_wheel_link"/>
	        <xacro:insert_block name="joint_axis"/>
	    </joint>

        <link name="${prefix}_wheel_link">
            <visual>
		        <geometry>
		            <mesh filename="package://nvt_description/meshes/STL/wheel/wheel.stl"/>
		        </geometry>
		        
                <material name="black">
    		        <color rgba="0.2 0.2 0.2 2.0"/>
                </material>
	        </visual>
	        
            <collision>
		        <origin xyz="0 -0.003 0" rpy="${-M_PI/2} 0 0"/>
		        <geometry>
		            <cylinder radius="${wheel_radius}" length="${wheel_length}"/>
		        </geometry>
	        </collision>
	        
            <inertial>
		        <origin xyz="0 -0.003 0" rpy="${-M_PI/2} 0 0"/>
		        <xacro:cylinder_inertia mass="${wheel_mass}"
						   radius="${wheel_radius}" length="${wheel_length}"/>
	        </inertial>
        </link>
    </xacro:macro>
</robot>
